# Genertor函数


## 1、简介

ES6提供的一种异步编程解决方法
语法上可以理解成：Generator函数是一个状态机，封装了多个内部状态

执行Generator函数会返回一个遍历器对象

Generator函数特征：
    1.function关键字与函数名之间有一个*号，
    2.函数体内部使用yield表达式，定义不同的内部状态

```
function* helloWorldGenerator() {
  yield 'hello';
  yield 'world';
  return 'ending';
}

var hw = helloWorldGenerator();
```
上面代码定义了一个Generator函数helloWorldGenerator，它内部有两个yield表达式（Hello和world），即该函数有三个状态：hello、world、return语句

然后，Generator 函数的调用方法与普通函数一样，也是在函数名后面加上一对圆括号。不同的是，调用 Generator 函数后，该函数并不执行，返回的也不是函数运行结果，而是一个指向内部状态的指针对象，也就是上一章介绍的遍历器对象（Iterator Object）。

_下一步，必须调用遍历器对象的next方法，使得指针移向下一个状态。也就是说，每次调用next方法，内部指针就从函数头部或上一次停下来的地方开始执行，直到遇到下一个yield表达式（或return语句）为止。换言之，Generator 函数是分段执行的，yield表达式是暂停执行的标记，而next方法可以恢复执行。_


**调用 Generator 函数，返回一个遍历器对象，代表 Generator 函数的内部指针。**

#


## yield表达式
由于Generator函数返回的遍历器对象，只有调用next方法才会遍历下一个内部状态，所以其实提供了一种可以暂停执行的函数，yield表达式就是暂停标志。

遍历器对象的next方法的运行逻辑如下：
 1.遇到yield表达式，就暂停执行后面的操作，并将紧跟在yield后面的那个表达式的值，作为返回的对象的value属性值
  2.下一次调用next方法时，再继续往下执行，直到遇到下一个yield表达式
  3.如果没有再遇到新的yield表达式，就一直运行到函数结束，直到return语句为止，并将return语句后面的表达式的值，作为返回的对象的value属性值。
  4.如果该函数没有return语句，则返回的对象的value属性值为undefined。


，yield表达式后面的表达式，只有当调用next方法、内部指针指向该语句时才会执行，因此等于为 JavaScript 提供了手动的“惰性求值”（Lazy Evaluation）的语法功能。
```

function* gen() {
  yield  123 + 456;
}

```

上面代码中，yield后面的表达式123 + 456，不会立即求值，只会在next方法将指针移到这一句时，才会求值。


yield表达式与return语句既有相似之处，也有区别。

- yield，函数暂停执行，下一次再从该位置继续向后执行，
- 而return语句不具备位置记忆的功能。

- 一个函数里面，只能执行一次（或者说一个）return语句，
- 但是可以执行多次（或者说多个）yield表达式。

- 正常函数只能返回一个值，因为只能执行一次return；
- Generator 函数可以返回一系列的值，因为可以有任意多个yield。

从另一个角度看，也可以说 Generator 生成了一系列的值，这也就是它的名称的来历（英语中，generator 这个词是“生成器”的意思）。

_Generator 函数可以不用yield表达式，这时就变成了一个单纯的暂缓执行函数。_

```
function* f() {
  console.log('执行了！')
}

var generator = f();

setTimeout(function () {
  generator.next()
}, 2000);
```
上面代码中，函数f如果是普通函数，在为变量generator赋值时就会执行。但是，函数f是一个 Generator 函数，就变成只有调用next方法时，函数f才会执行。

_另外需要注意，yield表达式只能用在 Generator 函数里面，用在其他地方都会报错。_

```
(function (){
  yield 1;
})()
// SyntaxError: Unexpected number
```
上面代码在一个普通函数中使用yield表达式，结果产生一个句法错误。


**另外，yield表达式如果用在另一个表达式之中，必须放在圆括号里面。**
```

function* demo() {
  console.log('Hello' + yield); // SyntaxError
  console.log('Hello' + yield 123); // SyntaxError

  console.log('Hello' + (yield)); // OK
  console.log('Hello' + (yield 123)); // OK
}
```

yield表达式用作函数参数或放在赋值表达式的右边，可以不加括号。

```
function* demo() {
  foo(yield 'a', yield 'b'); // OK
  let input = yield; // OK
}
```
## next方法的参数
**yield表达式本身没有返回值，或者总返回undefined。**
next方法可以带一个参数，**该参数**就会被当**作上一个yield表达式的返回值**

```
function* f() {
  for(var i = 0; true; i++) {
    var reset = yield i;
    if(reset) { i = -1; }
  }
}

var g = f();

g.next() // { value: 0, done: false }
g.next() // { value: 1, done: false }
g.next(true) // { value: 0, done: false }
```
上面代码先定义了一个可以无限运行的 Generator 函数f，如果next方法没有参数，每次运行到yield表达式，变量reset的值总是undefined。当next方法带一个参数true时，变量reset就被重置为这个参数（即true），因此i会等于-1，下一轮循环就会从-1开始递增。

这个功能有很重要的语法意义。Generator 函数从暂停状态到恢复运行，它的上下文状态（context）是不变的。通过next方法的参数，就有办法在 Generator 函数开始运行之后，继续向函数体内部注入值。也就是说，可以在 Generator 函数运行的不同阶段，从外部向内部注入不同的值，从而调整函数行为。

```
function* foo(x) {
  var y = 2 * (yield (x + 1));
  var z = yield (y / 3);
  return (x + y + z);
}

var a = foo(5);
a.next() // Object{value:6, done:false}
a.next() // Object{value:NaN, done:false}
a.next() // Object{value:NaN, done:true}

var b = foo(5);
b.next() // { value:6, done:false }
b.next(12) // { value:8, done:false }
b.next(13) // { value:42, done:true }

```
由于next方法的参数表示上一个yield表达式的返回值，所以在第一次使用next方法时，传递参数是无效的。V8 引擎直接忽略第一次使用next方法时的参数，只有从第二次使用next方法开始，参数才是有效的。从语义上讲，第一个next方法用来启动遍历器对象，所以不用带有参数。


## for ...of   循环
可以自动遍历Generator函数事生成的Iterator对象，且不需要在调用next()方法
```
function* foo() {
  yield 1;
  yield 2;
  yield 3;
  yield 4;
  yield 5;
  return 6;
}

for (let v of foo()) {
  console.log(v);
}
// 1 2 3 4 5
```
除了for...of循环以外，扩展运算符（...）、解构赋值和Array.from方法内部调用的，都是遍历器接口。这意味着，它们都可以将 Generator 函数返回的 Iterator 对象，作为参数。


```
function* numbers () {
  yield 1
  yield 2
  return 3
  yield 4
}

// 扩展运算符
[...numbers()] // [1, 2]

// Array.from 方法
Array.from(numbers()) // [1, 2]

// 解构赋值
let [x, y] = numbers();
x // 1
y // 2

// for...of 循环
for (let n of numbers()) {
  console.log(n)
}
// 1
// 2
```


#

## 4、Generator.prototype.throw()
Generator函数返回的遍历器对象，都有一个throw方法，可以在函数体外抛出错误，然后在Generator函数体外捕获
```
var g = function* () {
  try {
    yield;
  } catch (e) {
    console.log('内部捕获', e);
  }
};

var i = g();
i.next();

try {
  i.throw('a');
  i.throw('b');
} catch (e) {
  console.log('外部捕获', e);
}
// 内部捕获 a
// 外部捕获 b
```

_上面代码中，遍历器对象i连续抛出两个错误。第一个错误被 Generator 函数体内的catch语句捕获。i第二次抛出错误，由于 Generator 函数内部的catch语句已经执行过了，不会再捕捉到这个错误了，所以这个错误就被抛出了 Generator 函数体，被函数体外的catch语句捕获。_

throw方法可以接受一个参数，该参数会被catch语句接收，建议抛出Error对象的实例。
Generator 函数内部没有部署try...catch代码块，那么throw方法抛出的错误，将被外部try...catch代码块捕获

一旦 Generator 执行过程中抛出错误，且没有被内部捕获，就不会再执行下去了。如果此后还调用next方法，将返回一个value属性等于undefined、done属性等于true的对象，即 JavaScript 引擎认为这个 Generator 已经运行结束了。

```
function* g() {
  yield 1;
  console.log('throwing an exception');
  throw new Error('generator broke!');
  yield 2;
  yield 3;
}

function log(generator) {
  var v;
  console.log('starting generator');
  try {
    v = generator.next();
    console.log('第一次运行next方法', v);
  } catch (err) {
    console.log('捕捉错误', v);
  }
  try {
    v = generator.next();
    console.log('第二次运行next方法', v);
  } catch (err) {
    console.log('捕捉错误', v);
  }
  try {
    v = generator.next();
    console.log('第三次运行next方法', v);
  } catch (err) {
    console.log('捕捉错误', v);
  }
  console.log('caller done');
}

log(g());
// starting generator
// 第一次运行next方法 { value: 1, done: false }
// throwing an exception
// 捕捉错误 { value: 1, done: false }
// 第三次运行next方法 { value: undefined, done: true }
// caller done
```







































































